<?xml version="1.0" ?>

<robot name="mr_arm">
  <!-- Base link is the center of the robot's bottom plate -->
  <link name="link_0">
    <visual>
      <origin xyz="0 0 0" rpy="0 0 0" />
      <geometry>
        <mesh filename="meshes/Link0.stl" />
      </geometry>
    </visual>
    <collision>
      <origin xyz="0 0 0" rpy="0 0 0" />
      <geometry>
        <mesh filename="meshes/collision_Link0.stl" />
      </geometry>
    </collision>
  </link>

  <joint name="joint_1" type="revolute">
    <origin xyz="0 0 0" rpy="0 0 0" />
    <parent link="link_0" />
    <child link="link_1" />
    <axis xyz="0 0 1" />
    <limit effort="10.0" velocity="2.61799" lower="-3.141592" upper="3.141592" />
    <dynamics damping="0.5"/>
  </joint>

  <!-- Joint 1 -->
  <link name="link_1">
    <visual>
      <origin xyz="0 0 0" rpy="0 0 0" />
      <geometry>
        <mesh filename="meshes/Link1.stl" />
      </geometry>
    </visual>
    <collision>
      <origin xyz="0 0 0" rpy="0 0 0" />
      <geometry>
        <mesh filename="meshes/collision_Link1.stl" />
      </geometry>
    </collision>
  </link>

  <joint name="joint_2" type="revolute">
    <origin xyz="0 0 0.0575" rpy="0 0 0" />
    <parent link="link_1" />
    <child link="link_2" />
    <axis xyz="0 1 0" />
    <limit effort="10.0" velocity="2.61799" lower="-1.570796327" upper="1.570796327" />
    <dynamics damping="0.5"/>
  </joint>


  <link name="link_2">
    <visual>
      <origin xyz="0 0 0" rpy="0 0 0" />
      <geometry>
        <mesh filename="meshes/Link2.stl" />
      </geometry>
    </visual>
    <collision>
      <origin xyz="0 0 0" rpy="0 0 0" />
      <geometry>
        <mesh filename="meshes/collision_Link2.stl" />
      </geometry>
    </collision>
  </link>

  <joint name="joint_3" type="revolute">
    <origin xyz="0 0 0.5" rpy="0 0 0" />
    <parent link="link_2" />
    <child link="link_3" />
    <axis xyz="0 1 0" />
    <limit effort="10.0" velocity="2.61799" lower="-1.570796327" upper="1.570796327" />
    <dynamics damping="0.5"/>
  </joint>


  <link name="link_3">
    <visual>
      <origin xyz="0 0 0" rpy="0 0 0" />
      <geometry>
        <mesh filename="meshes/Link3.stl" />
      </geometry>
    </visual>
    <collision>
      <origin xyz="0 0 0" rpy="0 0 0" />
      <geometry>
        <mesh filename="meshes/collision_Link3.stl" />
      </geometry>
    </collision>
  </link>

  <joint name="joint_4" type="revolute">
    <origin xyz="0.4 0 0" rpy="0 0 0" />
    <parent link="link_3" />
    <child link="link_4" />
    <axis xyz="0 1 0" />
    <limit effort="10.0" velocity="2.61799" lower="-1.570796327" upper="1.570796327" />
    <dynamics damping="0.5"/>
  </joint>


  <link name="link_4">
    <visual>
      <origin xyz="0 0 0" rpy="0 0 0" />
      <geometry>
        <mesh filename="meshes/Link4.stl" />
      </geometry>
    </visual>
    <collision>
      <origin xyz="0 0 0" rpy="0 0 0" />
      <geometry>
        <mesh filename="meshes/collision_Link4.stl" />
      </geometry>
    </collision>
  </link>

  <joint name="joint_5" type="revolute">
    <origin xyz="0.034 0 0" rpy="0 0 0" />
    <parent link="link_4" />
    <child link="link_5" />
    <axis xyz="1 0 0" />
    <limit effort="10.0" velocity="2.61799" lower="-3.141592" upper="3.141592" />
    <dynamics damping="0.5"/>
  </joint>


  <link name="link_5">
    <visual>
      <origin xyz="0 0 0" rpy="0 0 0" />
      <geometry>
        <mesh filename="meshes/Link5.stl" />
      </geometry>
    </visual>
    <collision>
      <origin xyz="0 0 0" rpy="0 0 0" />
      <geometry>
        <mesh filename="meshes/collision_Link5.stl" />
      </geometry>
    </collision>
  </link>


</robot>
