<?xml version="1.0" ?>
<!-- =================================================================================== -->
<!-- |    This document was autogenerated by xacro from src/rover/rover_gazebo/urdf/rover.urdf.xacro | -->
<!-- |    EDITING THIS FILE BY HAND IS NOT RECOMMENDED                                 | -->
<!-- =================================================================================== -->
<robot name="rover">
  <link name="base_link">
    <inertial>
      <origin rpy="0 0 0" xyz="0 0 0"/>
      <mass value="45.2"/>
      <inertia ixx="1.7724" ixy="0.0" ixz="0.0" iyy="0.141558" iyz="-0.0" izz="0.179826"/>
    </inertial>
    <visual>
      <origin rpy="0 0 0" xyz="0 0 0"/>
      <geometry>
        <mesh filename="/home/helen/Documents/catkin_ws/src/rover/rover_gazebo/meshes/2Full_Asm_F2022.STL"/>
      </geometry>
    </visual>
    <collision>
      <origin rpy="0 0 0" xyz="0 0 -0.01"/>
      <geometry>
        <box size="0.25 0.25 0.02"/>
      </geometry>
    </collision>
  </link>
  <link name="base_footprint"/>
  <joint name="base_joint" type="fixed">
    <parent link="base_footprint"/>
    <child link="base_link"/>
    <origin rpy="0 0 0" xyz="0.0 0.0 0.0"/>
    <axis rpy="0 0 0" xyz="0 1 0"/>
  </joint>
  <!-- Wheel Link -->
  <link name="left_wheel_link">
    <inertial>
      <mass value="1.2"/>
      <origin xyz="0 0 0"/>
      <inertia ixx="0.142" ixy="0.0003118" ixz="0.0000392177" iyy="0.14155823" iyz="-0.000062645" izz="1.3729"/>
    </inertial>
    <visual>
      <origin rpy="0 0 1.570796325" xyz="0 0 0"/>
					<geometry>
						<cylinder length="0.02" radius="0.04688" />
					</geometry>
    </visual>
    <collision>
      <origin rpy="1.570796325 0 0" xyz="0 0 0"/>
      <geometry>
        <cylinder length="0.02" radius="0.04688"/>
      </geometry>
    </collision>
  </link>
  <!-- Wheel Joint -->
  <joint name="left_wheel" type="continuous">
    <parent link="base_link"/>
    <child link="left_wheel_link"/>
    <origin rpy="0 0 0" xyz="0.14 0.14 -0.045"/>
    <axis rpy="0 0 0" xyz="0 1 0"/>
    <limit effort="30" velocity="1.0"/>
    <!-- <dynamics damping="1" friction="100.0" /> -->
  </joint>
  <gazebo reference="left_wheel_link">
    <mu1 value="200"/>
    <mu2 value="100"/>
    <kp value="10000000.0"/>
    <kd value="1.0"/>
    <material>Gazebo/Grey</material>
  </gazebo>
  <transmission name="left_wheel_trans">
    <type>transmission_interface/SimpleTransmission</type>
    <actuator name="left_wheel_motor">
      <mechanicalReduction>1</mechanicalReduction>
    </actuator>
    <joint name="left_wheel">
      <hardwareInterface>hardware_interface/VelocityJointInterface</hardwareInterface>
    </joint>
  </transmission>
  <!-- Wheel Link -->
  <link name="right_wheel_link">
    <inertial>
      <mass value="1.2"/>
      <origin xyz="0 0 0"/>
      <inertia ixx="0.142" ixy="0.0003118" ixz="0.0000392177" iyy="0.14155823" iyz="-0.000062645" izz="1.3729"/>
    </inertial>
    <visual>
      <origin rpy="0 0 1.570796325" xyz="0 0 0"/>
      <geometry>
						<cylinder length="0.02" radius="0.04688" />
					</geometry>
    </visual>
    <collision>
      <origin rpy="1.570796325 0 0" xyz="0 0 0"/>
      <geometry>
        <cylinder length="0.02" radius="0.04688"/>
      </geometry>
    </collision>
  </link>
  <!-- Wheel Joint -->
  <joint name="right_wheel" type="continuous">
    <parent link="base_link"/>
    <child link="right_wheel_link"/>
    <origin rpy="0 0 0" xyz="3.14 -0.14 -0.045"/>
    <axis rpy="0 0 0" xyz="0 1 0"/>
    <limit effort="30" velocity="1.0"/>
    <!-- <dynamics damping="1" friction="100.0" /> -->
  </joint>
  <gazebo reference="right_wheel_link">
    <mu1 value="200"/>
    <mu2 value="100"/>
    <kp value="10000000.0"/>
    <kd value="1.0"/>
    <material>Gazebo/Grey</material>
  </gazebo>
  <transmission name="right_wheel_trans">
    <type>transmission_interface/SimpleTransmission</type>
    <actuator name="right_wheel_motor">
      <mechanicalReduction>1</mechanicalReduction>
    </actuator>
    <joint name="right_wheel">
      <hardwareInterface>hardware_interface/VelocityJointInterface</hardwareInterface>
    </joint>
  </transmission>
  <!-- Wheel Link -->
  <link name="rear_left_wheel_link">
    <inertial>
      <mass value="1.2"/>
      <origin xyz="0 0 0"/>
      <inertia ixx="0.142" ixy="0.0003118" ixz="0.0000392177" iyy="0.14155823" iyz="-0.000062645" izz="1.3729"/>
    </inertial>
    <visual>
      <origin rpy="0 0 1.570796325" xyz="0 0 0"/>
      <geometry>
						<cylinder length="0.02" radius="0.04688" />
					</geometry>
    </visual>
    <collision>
      <origin rpy="1.570796325 0 0" xyz="0 0 0"/>
      <geometry>
        <cylinder length="0.02" radius="0.04688"/>
      </geometry>
    </collision>
  </link>
  <!-- Wheel Joint -->
  <joint name="rear_left_wheel" type="continuous">
    <parent link="base_link"/>
    <child link="rear_left_wheel_link"/>
    <origin rpy="0 0 0" xyz="-0.14 0.14 -0.045"/>
    <axis rpy="0 0 0" xyz="0 1 0"/>
    <limit effort="30" velocity="1.0"/>
    <!-- <dynamics damping="1" friction="100.0" /> -->
  </joint>
  <gazebo reference="rear_left_wheel_link">
    <mu1 value="200"/>
    <mu2 value="100"/>
    <kp value="10000000.0"/>
    <kd value="1.0"/>
    <material>Gazebo/Grey</material>
  </gazebo>
  <transmission name="rear_left_wheel_trans">
    <type>transmission_interface/SimpleTransmission</type>
    <actuator name="rear_left_wheel_motor">
      <mechanicalReduction>1</mechanicalReduction>
    </actuator>
    <joint name="rear_left_wheel">
      <hardwareInterface>hardware_interface/VelocityJointInterface</hardwareInterface>
    </joint>
  </transmission>
  <!-- Wheel Link -->
  <link name="rear_right_wheel_link">
    <inertial>
      <mass value="1.2"/>
      <origin xyz="0 0 0"/>
      <inertia ixx="0.142" ixy="0.0003118" ixz="0.0000392177" iyy="0.14155823" iyz="-0.000062645" izz="1.3729"/>
    </inertial>
    <visual>
      <origin rpy="0 0 1.570796325" xyz="0 0 0"/>
      <geometry>
						<cylinder length="0.02" radius="0.04688" />
					</geometry>
    </visual>
    <collision>
      <origin rpy="1.570796325 0 0" xyz="0 0 0"/>
      <geometry>
        <cylinder length="0.02" radius="0.04688"/>
      </geometry>
    </collision>
  </link>
  <!-- Wheel Joint -->
  <joint name="rear_right_wheel" type="continuous">
    <parent link="base_link"/>
    <child link="rear_right_wheel_link"/>
    <origin rpy="0 0 0" xyz="-0.14 -0.14 -0.045"/>
    <axis rpy="0 0 0" xyz="0 1 0"/>
    <limit effort="30" velocity="1.0"/>
    <!-- <dynamics damping="1" friction="100.0" /> -->
  </joint>
  <gazebo reference="rear_right_wheel_link">
    <mu1 value="200"/>
    <mu2 value="100"/>
    <kp value="10000000.0"/>
    <kd value="1.0"/>
    <material>Gazebo/Grey</material>
  </gazebo>
  <transmission name="rear_right_wheel_trans">
    <type>transmission_interface/SimpleTransmission</type>
    <actuator name="rear_right_wheel_motor">
      <mechanicalReduction>1</mechanicalReduction>
    </actuator>
    <joint name="rear_right_wheel">
      <hardwareInterface>hardware_interface/VelocityJointInterface</hardwareInterface>
    </joint>
  </transmission>
  <gazebo>
    <plugin filename="libgazebo_ros_control.so" name="gazebo_ros_control">
      <robotNamespace>/</robotNamespace>
      <!-- <robotNamespace>$(arg robot_namespace)</robotNamespace> -->
      <!-- <legacyModeNS>true</legacyModeNS> -->
    </plugin>
  </gazebo>
</robot>

